Workbook

Sheet Guide
B1: 340 Collective Risk Register: Guide
B2: Project 07 lab (spreadsheet version). Fill in the yellow cells on the Risk Register tab; everything else calculates automatically.
B4: How to use
B5: Yellow cells | C5: Your inputs: category, description, likelihood, impact, mitigation, owner, residual likelihood and impact, review date.
B6: White cells | C6: Formulas. Don't type in them: Risk Score, Rating, Residual Risk, Residual Rating, and the Heat Map and Summary tabs fill in by themselves.
B7: Row R-01 | C7: An example row showing the expected format. Keep it, edit it, or replace it with your own risk.
B9: Likelihood (1 to 5)
B10: 1 Rare | C10: Very unlikely; could happen only in unusual situations.
B11: 2 Unlikely | C11: Could happen, but not expected within a year.
B12: 3 Possible | C12: Might happen within a year.
B13: 4 Likely | C13: Will probably happen within a year.
B14: 5 Almost certain | C14: Expected to happen, or already happening.
B16: Impact (1 to 5)
B17: 1 Minimal | C17: Little effect; fixed quickly at almost no cost.
B18: 2 Minor | C18: Small disruption or cost; clients barely notice.
B19: 3 Moderate | C19: Noticeable disruption, some lost revenue, or a few unhappy clients.
B20: 4 Major | C20: Serious outage, data loss, payment fraud, or reputation damage.
B21: 5 Severe | C21: Business-threatening: major breach, account takeover, or legal trouble.
B23: Rating thresholds
B24: High | C24: Score 15 to 25: act now, report to leadership.
B25: Medium | C25: Score 8 to 14: plan a fix and review regularly.
B26: Low | C26: Score 1 to 7: monitor, or accept.
B27: Note | C27: Thresholds are a common starting point, not a standard. Agree final thresholds with the ISSM.
B29: Lab steps
B30: 1 | C30: Fill in the register columns for each risk.
B31: 2 | C31: Identify at least 12 risks across security, vendor, and business categories.
B32: 3 | C32: Risk Score = Likelihood x Impact (automatic, color-coded High / Medium / Low).
B33: 4 | C33: Write a mitigation and owner for each risk, then re-score for Residual Risk.
B34: 5 | C34: Check the 5x5 Heat Map tab (automatic).
B35: 6 | C35: Write the half-page risk summary on the Summary tab.
B37: Risk ideas from the lab | C37: Compromised AWS credentials; Stripe payment link misuse; domain registrar lapse; loss of client files; single-person dependency.
B38: Owners | C38: Use roles, not personal names or emails (governance rule), e.g. ISSM, ISSE, Business Owner, Account Admin.

Sheet Heat Map
A1: 5x5 Risk Heat Map
A2: Risk IDs appear automatically in the cell matching their likelihood and impact.
A4: Inherent risk (before mitigation)
B5: 5 | C5: =TEXTJOIN(", ",TRUE(),IF('Risk Register'!$O$5="5-1",'Risk Register'!$A$5,""),IF('Risk Register'!$O$6="5-1",'Risk Register'!$A$6,""),IF('Risk Register'!$O$7="5-1",'Risk Register'!$A$7,""),IF('Risk Register'!$O$8="5-1",'Risk Register'!$A$8,""),IF('Risk Register'!$O$9="5-1",'Risk Register'!$A$9,""),IF('Risk Register'!$O$10="5-1",'Risk Register'!$A$10,""),IF('Risk Register'!$O$11="5-1",'Risk Register'!$A$11,""),IF('Risk Register'!$O$12="5-1",'Risk Register'!$A$12,""),IF('Risk Register'!$O$13="5-1",'Risk Register'!$A$13,""),IF('Risk Register'!$O$14="5-1",'Risk Register'!$A$14,""),IF('Risk Register'!$O$15="5-1",'Risk Register'!$A$15,""),IF('Risk Register'!$O$16="5-1",'Risk Register'!$A$16,""),IF('Risk Register'!$O$17="5-1",'Risk Register'!$A$17,""),IF('Risk Register'!$O$18="5-1",'Risk Register'!$A$18,""),IF('Risk Register'!$O$19="5-1",'Risk Register'!$A$19,"")) | D5: =TEXTJOIN(", ",TRUE(),IF('Risk Register'!$O$5="5-2",'Risk Register'!$A$5,""),IF('Risk Register'!$O$6="5-2",'Risk Register'!$A$6,""),IF('Risk Register'!$O$7="5-2",'Risk Register'!$A$7,""),IF('Risk Register'!$O$8="5-2",'Risk Register'!$A$8,""),IF('Risk Register'!$O$9="5-2",'Risk Register'!$A$9,""),IF('Risk Register'!$O$10="5-2",'Risk Register'!$A$10,""),IF('Risk Register'!$O$11="5-2",'Risk Register'!$A$11,""),IF('Risk Register'!$O$12="5-2",'Risk Register'!$A$12,""),IF('Risk Register'!$O$13="5-2",'Risk Register'!$A$13,""),IF('Risk Register'!$O$14="5-2",'Risk Register'!$A$14,""),IF('Risk Register'!$O$15="5-2",'Risk Register'!$A$15,""),IF('Risk Register'!$O$16="5-2",'Risk Register'!$A$16,""),IF('Risk Register'!$O$17="5-2",'Risk Register'!$A$17,""),IF('Risk Register'!$O$18="5-2",'Risk Register'!$A$18,""),IF('Risk Register'!$O$19="5-2",'Risk Register'!$A$19,"")) | E5: =TEXTJOIN(", ",TRUE(),IF('Risk Register'!$O$5="5-3",'Risk Register'!$A$5,""),IF('Risk Register'!$O$6="5-3",'Risk Register'!$A$6,""),IF('Risk Register'!$O$7="5-3",'Risk Register'!$A$7,""),IF('Risk Register'!$O$8="5-3",'Risk Register'!$A$8,""),IF('Risk Register'!$O$9="5-3",'Risk Register'!$A$9,""),IF('Risk Register'!$O$10="5-3",'Risk Register'!$A$10,""),IF('Risk Register'!$O$11="5-3",'Risk Register'!$A$11,""),IF('Risk Register'!$O$12="5-3",'Risk Register'!$A$12,""),IF('Risk Register'!$O$13="5-3",'Risk Register'!$A$13,""),IF('Risk Register'!$O$14="5-3",'Risk Register'!$A$14,""),IF('Risk Register'!$O$15="5-3",'Risk Register'!$A$15,""),IF('Risk Register'!$O$16="5-3",'Risk Register'!$A$16,""),IF('Risk Register'!$O$17="5-3",'Risk Register'!$A$17,""),IF('Risk Register'!$O$18="5-3",'Risk Register'!$A$18,""),IF('Risk Register'!$O$19="5-3",'Risk Register'!$A$19,"")) | F5: =TEXTJOIN(", ",TRUE(),IF('Risk Register'!$O$5="5-4",'Risk Register'!$A$5,""),IF('Risk Register'!$O$6="5-4",'Risk Register'!$A$6,""),IF('Risk Register'!$O$7="5-4",'Risk Register'!$A$7,""),IF('Risk Register'!$O$8="5-4",'Risk Register'!$A$8,""),IF('Risk Register'!$O$9="5-4",'Risk Register'!$A$9,""),IF('Risk Register'!$O$10="5-4",'Risk Register'!$A$10,""),IF('Risk Register'!$O$11="5-4",'Risk Register'!$A$11,""),IF('Risk Register'!$O$12="5-4",'Risk Register'!$A$12,""),IF('Risk Register'!$O$13="5-4",'Risk Register'!$A$13,""),IF('Risk Register'!$O$14="5-4",'Risk Register'!$A$14,""),IF('Risk Register'!$O$15="5-4",'Risk Register'!$A$15,""),IF('Risk Register'!$O$16="5-4",'Risk Register'!$A$16,""),IF('Risk Register'!$O$17="5-4",'Risk Register'!$A$17,""),IF('Risk Register'!$O$18="5-4",'Risk Register'!$A$18,""),IF('Risk Register'!$O$19="5-4",'Risk Register'!$A$19,"")) | G5: =TEXTJOIN(", ",TRUE(),IF('Risk Register'!$O$5="5-5",'Risk Register'!$A$5,""),IF('Risk Register'!$O$6="5-5",'Risk Register'!$A$6,""),IF('Risk Register'!$O$7="5-5",'Risk Register'!$A$7,""),IF('Risk Register'!$O$8="5-5",'Risk Register'!$A$8,""),IF('Risk Register'!$O$9="5-5",'Risk Register'!$A$9,""),IF('Risk Register'!$O$10="5-5",'Risk Register'!$A$10,""),IF('Risk Register'!$O$11="5-5",'Risk Register'!$A$11,""),IF('Risk Register'!$O$12="5-5",'Risk Register'!$A$12,""),IF('Risk Register'!$O$13="5-5",'Risk Register'!$A$13,""),IF('Risk Register'!$O$14="5-5",'Risk Register'!$A$14,""),IF('Risk Register'!$O$15="5-5",'Risk Register'!$A$15,""),IF('Risk Register'!$O$16="5-5",'Risk Register'!$A$16,""),IF('Risk Register'!$O$17="5-5",'Risk Register'!$A$17,""),IF('Risk Register'!$O$18="5-5",'Risk Register'!$A$18,""),IF('Risk Register'!$O$19="5-5",'Risk Register'!$A$19,"")) | I5: Legend
B6: 4 | C6: =TEXTJOIN(", ",TRUE(),IF('Risk Register'!$O$5="4-1",'Risk Register'!$A$5,""),IF('Risk Register'!$O$6="4-1",'Risk Register'!$A$6,""),IF('Risk Register'!$O$7="4-1",'Risk Register'!$A$7,""),IF('Risk Register'!$O$8="4-1",'Risk Register'!$A$8,""),IF('Risk Register'!$O$9="4-1",'Risk Register'!$A$9,""),IF('Risk Register'!$O$10="4-1",'Risk Register'!$A$10,""),IF('Risk Register'!$O$11="4-1",'Risk Register'!$A$11,""),IF('Risk Register'!$O$12="4-1",'Risk Register'!$A$12,""),IF('Risk Register'!$O$13="4-1",'Risk Register'!$A$13,""),IF('Risk Register'!$O$14="4-1",'Risk Register'!$A$14,""),IF('Risk Register'!$O$15="4-1",'Risk Register'!$A$15,""),IF('Risk Register'!$O$16="4-1",'Risk Register'!$A$16,""),IF('Risk Register'!$O$17="4-1",'Risk Register'!$A$17,""),IF('Risk Register'!$O$18="4-1",'Risk Register'!$A$18,""),IF('Risk Register'!$O$19="4-1",'Risk Register'!$A$19,"")) | D6: =TEXTJOIN(", ",TRUE(),IF('Risk Register'!$O$5="4-2",'Risk Register'!$A$5,""),IF('Risk Register'!$O$6="4-2",'Risk Register'!$A$6,""),IF('Risk Register'!$O$7="4-2",'Risk Register'!$A$7,""),IF('Risk Register'!$O$8="4-2",'Risk Register'!$A$8,""),IF('Risk Register'!$O$9="4-2",'Risk Register'!$A$9,""),IF('Risk Register'!$O$10="4-2",'Risk Register'!$A$10,""),IF('Risk Register'!$O$11="4-2",'Risk Register'!$A$11,""),IF('Risk Register'!$O$12="4-2",'Risk Register'!$A$12,""),IF('Risk Register'!$O$13="4-2",'Risk Register'!$A$13,""),IF('Risk Register'!$O$14="4-2",'Risk Register'!$A$14,""),IF('Risk Register'!$O$15="4-2",'Risk Register'!$A$15,""),IF('Risk Register'!$O$16="4-2",'Risk Register'!$A$16,""),IF('Risk Register'!$O$17="4-2",'Risk Register'!$A$17,""),IF('Risk Register'!$O$18="4-2",'Risk Register'!$A$18,""),IF('Risk Register'!$O$19="4-2",'Risk Register'!$A$19,"")) | E6: =TEXTJOIN(", ",TRUE(),IF('Risk Register'!$O$5="4-3",'Risk Register'!$A$5,""),IF('Risk Register'!$O$6="4-3",'Risk Register'!$A$6,""),IF('Risk Register'!$O$7="4-3",'Risk Register'!$A$7,""),IF('Risk Register'!$O$8="4-3",'Risk Register'!$A$8,""),IF('Risk Register'!$O$9="4-3",'Risk Register'!$A$9,""),IF('Risk Register'!$O$10="4-3",'Risk Register'!$A$10,""),IF('Risk Register'!$O$11="4-3",'Risk Register'!$A$11,""),IF('Risk Register'!$O$12="4-3",'Risk Register'!$A$12,""),IF('Risk Register'!$O$13="4-3",'Risk Register'!$A$13,""),IF('Risk Register'!$O$14="4-3",'Risk Register'!$A$14,""),IF('Risk Register'!$O$15="4-3",'Risk Register'!$A$15,""),IF('Risk Register'!$O$16="4-3",'Risk Register'!$A$16,""),IF('Risk Register'!$O$17="4-3",'Risk Register'!$A$17,""),IF('Risk Register'!$O$18="4-3",'Risk Register'!$A$18,""),IF('Risk Register'!$O$19="4-3",'Risk Register'!$A$19,"")) | F6: =TEXTJOIN(", ",TRUE(),IF('Risk Register'!$O$5="4-4",'Risk Register'!$A$5,""),IF('Risk Register'!$O$6="4-4",'Risk Register'!$A$6,""),IF('Risk Register'!$O$7="4-4",'Risk Register'!$A$7,""),IF('Risk Register'!$O$8="4-4",'Risk Register'!$A$8,""),IF('Risk Register'!$O$9="4-4",'Risk Register'!$A$9,""),IF('Risk Register'!$O$10="4-4",'Risk Register'!$A$10,""),IF('Risk Register'!$O$11="4-4",'Risk Register'!$A$11,""),IF('Risk Register'!$O$12="4-4",'Risk Register'!$A$12,""),IF('Risk Register'!$O$13="4-4",'Risk Register'!$A$13,""),IF('Risk Register'!$O$14="4-4",'Risk Register'!$A$14,""),IF('Risk Register'!$O$15="4-4",'Risk Register'!$A$15,""),IF('Risk Register'!$O$16="4-4",'Risk Register'!$A$16,""),IF('Risk Register'!$O$17="4-4",'Risk Register'!$A$17,""),IF('Risk Register'!$O$18="4-4",'Risk Register'!$A$18,""),IF('Risk Register'!$O$19="4-4",'Risk Register'!$A$19,"")) -> R-02, R-05, R-08 | G6: =TEXTJOIN(", ",TRUE(),IF('Risk Register'!$O$5="4-5",'Risk Register'!$A$5,""),IF('Risk Register'!$O$6="4-5",'Risk Register'!$A$6,""),IF('Risk Register'!$O$7="4-5",'Risk Register'!$A$7,""),IF('Risk Register'!$O$8="4-5",'Risk Register'!$A$8,""),IF('Risk Register'!$O$9="4-5",'Risk Register'!$A$9,""),IF('Risk Register'!$O$10="4-5",'Risk Register'!$A$10,""),IF('Risk Register'!$O$11="4-5",'Risk Register'!$A$11,""),IF('Risk Register'!$O$12="4-5",'Risk Register'!$A$12,""),IF('Risk Register'!$O$13="4-5",'Risk Register'!$A$13,""),IF('Risk Register'!$O$14="4-5",'Risk Register'!$A$14,""),IF('Risk Register'!$O$15="4-5",'Risk Register'!$A$15,""),IF('Risk Register'!$O$16="4-5",'Risk Register'!$A$16,""),IF('Risk Register'!$O$17="4-5",'Risk Register'!$A$17,""),IF('Risk Register'!$O$18="4-5",'Risk Register'!$A$18,""),IF('Risk Register'!$O$19="4-5",'Risk Register'!$A$19,"")) -> R-01 | I6: High (15-25)
A7: Likelihood ↑ | B7: 3 | C7: =TEXTJOIN(", ",TRUE(),IF('Risk Register'!$O$5="3-1",'Risk Register'!$A$5,""),IF('Risk Register'!$O$6="3-1",'Risk Register'!$A$6,""),IF('Risk Register'!$O$7="3-1",'Risk Register'!$A$7,""),IF('Risk Register'!$O$8="3-1",'Risk Register'!$A$8,""),IF('Risk Register'!$O$9="3-1",'Risk Register'!$A$9,""),IF('Risk Register'!$O$10="3-1",'Risk Register'!$A$10,""),IF('Risk Register'!$O$11="3-1",'Risk Register'!$A$11,""),IF('Risk Register'!$O$12="3-1",'Risk Register'!$A$12,""),IF('Risk Register'!$O$13="3-1",'Risk Register'!$A$13,""),IF('Risk Register'!$O$14="3-1",'Risk Register'!$A$14,""),IF('Risk Register'!$O$15="3-1",'Risk Register'!$A$15,""),IF('Risk Register'!$O$16="3-1",'Risk Register'!$A$16,""),IF('Risk Register'!$O$17="3-1",'Risk Register'!$A$17,""),IF('Risk Register'!$O$18="3-1",'Risk Register'!$A$18,""),IF('Risk Register'!$O$19="3-1",'Risk Register'!$A$19,"")) | D7: =TEXTJOIN(", ",TRUE(),IF('Risk Register'!$O$5="3-2",'Risk Register'!$A$5,""),IF('Risk Register'!$O$6="3-2",'Risk Register'!$A$6,""),IF('Risk Register'!$O$7="3-2",'Risk Register'!$A$7,""),IF('Risk Register'!$O$8="3-2",'Risk Register'!$A$8,""),IF('Risk Register'!$O$9="3-2",'Risk Register'!$A$9,""),IF('Risk Register'!$O$10="3-2",'Risk Register'!$A$10,""),IF('Risk Register'!$O$11="3-2",'Risk Register'!$A$11,""),IF('Risk Register'!$O$12="3-2",'Risk Register'!$A$12,""),IF('Risk Register'!$O$13="3-2",'Risk Register'!$A$13,""),IF('Risk Register'!$O$14="3-2",'Risk Register'!$A$14,""),IF('Risk Register'!$O$15="3-2",'Risk Register'!$A$15,""),IF('Risk Register'!$O$16="3-2",'Risk Register'!$A$16,""),IF('Risk Register'!$O$17="3-2",'Risk Register'!$A$17,""),IF('Risk Register'!$O$18="3-2",'Risk Register'!$A$18,""),IF('Risk Register'!$O$19="3-2",'Risk Register'!$A$19,"")) -> R-12 | E7: =TEXTJOIN(", ",TRUE(),IF('Risk Register'!$O$5="3-3",'Risk Register'!$A$5,""),IF('Risk Register'!$O$6="3-3",'Risk Register'!$A$6,""),IF('Risk Register'!$O$7="3-3",'Risk Register'!$A$7,""),IF('Risk Register'!$O$8="3-3",'Risk Register'!$A$8,""),IF('Risk Register'!$O$9="3-3",'Risk Register'!$A$9,""),IF('Risk Register'!$O$10="3-3",'Risk Register'!$A$10,""),IF('Risk Register'!$O$11="3-3",'Risk Register'!$A$11,""),IF('Risk Register'!$O$12="3-3",'Risk Register'!$A$12,""),IF('Risk Register'!$O$13="3-3",'Risk Register'!$A$13,""),IF('Risk Register'!$O$14="3-3",'Risk Register'!$A$14,""),IF('Risk Register'!$O$15="3-3",'Risk Register'!$A$15,""),IF('Risk Register'!$O$16="3-3",'Risk Register'!$A$16,""),IF('Risk Register'!$O$17="3-3",'Risk Register'!$A$17,""),IF('Risk Register'!$O$18="3-3",'Risk Register'!$A$18,""),IF('Risk Register'!$O$19="3-3",'Risk Register'!$A$19,"")) -> R-09, R-10 | F7: =TEXTJOIN(", ",TRUE(),IF('Risk Register'!$O$5="3-4",'Risk Register'!$A$5,""),IF('Risk Register'!$O$6="3-4",'Risk Register'!$A$6,""),IF('Risk Register'!$O$7="3-4",'Risk Register'!$A$7,""),IF('Risk Register'!$O$8="3-4",'Risk Register'!$A$8,""),IF('Risk Register'!$O$9="3-4",'Risk Register'!$A$9,""),IF('Risk Register'!$O$10="3-4",'Risk Register'!$A$10,""),IF('Risk Register'!$O$11="3-4",'Risk Register'!$A$11,""),IF('Risk Register'!$O$12="3-4",'Risk Register'!$A$12,""),IF('Risk Register'!$O$13="3-4",'Risk Register'!$A$13,""),IF('Risk Register'!$O$14="3-4",'Risk Register'!$A$14,""),IF('Risk Register'!$O$15="3-4",'Risk Register'!$A$15,""),IF('Risk Register'!$O$16="3-4",'Risk Register'!$A$16,""),IF('Risk Register'!$O$17="3-4",'Risk Register'!$A$17,""),IF('Risk Register'!$O$18="3-4",'Risk Register'!$A$18,""),IF('Risk Register'!$O$19="3-4",'Risk Register'!$A$19,"")) -> R-04 | G7: =TEXTJOIN(", ",TRUE(),IF('Risk Register'!$O$5="3-5",'Risk Register'!$A$5,""),IF('Risk Register'!$O$6="3-5",'Risk Register'!$A$6,""),IF('Risk Register'!$O$7="3-5",'Risk Register'!$A$7,""),IF('Risk Register'!$O$8="3-5",'Risk Register'!$A$8,""),IF('Risk Register'!$O$9="3-5",'Risk Register'!$A$9,""),IF('Risk Register'!$O$10="3-5",'Risk Register'!$A$10,""),IF('Risk Register'!$O$11="3-5",'Risk Register'!$A$11,""),IF('Risk Register'!$O$12="3-5",'Risk Register'!$A$12,""),IF('Risk Register'!$O$13="3-5",'Risk Register'!$A$13,""),IF('Risk Register'!$O$14="3-5",'Risk Register'!$A$14,""),IF('Risk Register'!$O$15="3-5",'Risk Register'!$A$15,""),IF('Risk Register'!$O$16="3-5",'Risk Register'!$A$16,""),IF('Risk Register'!$O$17="3-5",'Risk Register'!$A$17,""),IF('Risk Register'!$O$18="3-5",'Risk Register'!$A$18,""),IF('Risk Register'!$O$19="3-5",'Risk Register'!$A$19,"")) | I7: Medium (8-14)
B8: 2 | C8: =TEXTJOIN(", ",TRUE(),IF('Risk Register'!$O$5="2-1",'Risk Register'!$A$5,""),IF('Risk Register'!$O$6="2-1",'Risk Register'!$A$6,""),IF('Risk Register'!$O$7="2-1",'Risk Register'!$A$7,""),IF('Risk Register'!$O$8="2-1",'Risk Register'!$A$8,""),IF('Risk Register'!$O$9="2-1",'Risk Register'!$A$9,""),IF('Risk Register'!$O$10="2-1",'Risk Register'!$A$10,""),IF('Risk Register'!$O$11="2-1",'Risk Register'!$A$11,""),IF('Risk Register'!$O$12="2-1",'Risk Register'!$A$12,""),IF('Risk Register'!$O$13="2-1",'Risk Register'!$A$13,""),IF('Risk Register'!$O$14="2-1",'Risk Register'!$A$14,""),IF('Risk Register'!$O$15="2-1",'Risk Register'!$A$15,""),IF('Risk Register'!$O$16="2-1",'Risk Register'!$A$16,""),IF('Risk Register'!$O$17="2-1",'Risk Register'!$A$17,""),IF('Risk Register'!$O$18="2-1",'Risk Register'!$A$18,""),IF('Risk Register'!$O$19="2-1",'Risk Register'!$A$19,"")) | D8: =TEXTJOIN(", ",TRUE(),IF('Risk Register'!$O$5="2-2",'Risk Register'!$A$5,""),IF('Risk Register'!$O$6="2-2",'Risk Register'!$A$6,""),IF('Risk Register'!$O$7="2-2",'Risk Register'!$A$7,""),IF('Risk Register'!$O$8="2-2",'Risk Register'!$A$8,""),IF('Risk Register'!$O$9="2-2",'Risk Register'!$A$9,""),IF('Risk Register'!$O$10="2-2",'Risk Register'!$A$10,""),IF('Risk Register'!$O$11="2-2",'Risk Register'!$A$11,""),IF('Risk Register'!$O$12="2-2",'Risk Register'!$A$12,""),IF('Risk Register'!$O$13="2-2",'Risk Register'!$A$13,""),IF('Risk Register'!$O$14="2-2",'Risk Register'!$A$14,""),IF('Risk Register'!$O$15="2-2",'Risk Register'!$A$15,""),IF('Risk Register'!$O$16="2-2",'Risk Register'!$A$16,""),IF('Risk Register'!$O$17="2-2",'Risk Register'!$A$17,""),IF('Risk Register'!$O$18="2-2",'Risk Register'!$A$18,""),IF('Risk Register'!$O$19="2-2",'Risk Register'!$A$19,"")) | E8: =TEXTJOIN(", ",TRUE(),IF('Risk Register'!$O$5="2-3",'Risk Register'!$A$5,""),IF('Risk Register'!$O$6="2-3",'Risk Register'!$A$6,""),IF('Risk Register'!$O$7="2-3",'Risk Register'!$A$7,""),IF('Risk Register'!$O$8="2-3",'Risk Register'!$A$8,""),IF('Risk Register'!$O$9="2-3",'Risk Register'!$A$9,""),IF('Risk Register'!$O$10="2-3",'Risk Register'!$A$10,""),IF('Risk Register'!$O$11="2-3",'Risk Register'!$A$11,""),IF('Risk Register'!$O$12="2-3",'Risk Register'!$A$12,""),IF('Risk Register'!$O$13="2-3",'Risk Register'!$A$13,""),IF('Risk Register'!$O$14="2-3",'Risk Register'!$A$14,""),IF('Risk Register'!$O$15="2-3",'Risk Register'!$A$15,""),IF('Risk Register'!$O$16="2-3",'Risk Register'!$A$16,""),IF('Risk Register'!$O$17="2-3",'Risk Register'!$A$17,""),IF('Risk Register'!$O$18="2-3",'Risk Register'!$A$18,""),IF('Risk Register'!$O$19="2-3",'Risk Register'!$A$19,"")) -> R-07 | F8: =TEXTJOIN(", ",TRUE(),IF('Risk Register'!$O$5="2-4",'Risk Register'!$A$5,""),IF('Risk Register'!$O$6="2-4",'Risk Register'!$A$6,""),IF('Risk Register'!$O$7="2-4",'Risk Register'!$A$7,""),IF('Risk Register'!$O$8="2-4",'Risk Register'!$A$8,""),IF('Risk Register'!$O$9="2-4",'Risk Register'!$A$9,""),IF('Risk Register'!$O$10="2-4",'Risk Register'!$A$10,""),IF('Risk Register'!$O$11="2-4",'Risk Register'!$A$11,""),IF('Risk Register'!$O$12="2-4",'Risk Register'!$A$12,""),IF('Risk Register'!$O$13="2-4",'Risk Register'!$A$13,""),IF('Risk Register'!$O$14="2-4",'Risk Register'!$A$14,""),IF('Risk Register'!$O$15="2-4",'Risk Register'!$A$15,""),IF('Risk Register'!$O$16="2-4",'Risk Register'!$A$16,""),IF('Risk Register'!$O$17="2-4",'Risk Register'!$A$17,""),IF('Risk Register'!$O$18="2-4",'Risk Register'!$A$18,""),IF('Risk Register'!$O$19="2-4",'Risk Register'!$A$19,"")) -> R-03, R-11 | G8: =TEXTJOIN(", ",TRUE(),IF('Risk Register'!$O$5="2-5",'Risk Register'!$A$5,""),IF('Risk Register'!$O$6="2-5",'Risk Register'!$A$6,""),IF('Risk Register'!$O$7="2-5",'Risk Register'!$A$7,""),IF('Risk Register'!$O$8="2-5",'Risk Register'!$A$8,""),IF('Risk Register'!$O$9="2-5",'Risk Register'!$A$9,""),IF('Risk Register'!$O$10="2-5",'Risk Register'!$A$10,""),IF('Risk Register'!$O$11="2-5",'Risk Register'!$A$11,""),IF('Risk Register'!$O$12="2-5",'Risk Register'!$A$12,""),IF('Risk Register'!$O$13="2-5",'Risk Register'!$A$13,""),IF('Risk Register'!$O$14="2-5",'Risk Register'!$A$14,""),IF('Risk Register'!$O$15="2-5",'Risk Register'!$A$15,""),IF('Risk Register'!$O$16="2-5",'Risk Register'!$A$16,""),IF('Risk Register'!$O$17="2-5",'Risk Register'!$A$17,""),IF('Risk Register'!$O$18="2-5",'Risk Register'!$A$18,""),IF('Risk Register'!$O$19="2-5",'Risk Register'!$A$19,"")) -> R-06 | I8: Low (1-7)
B9: 1 | C9: =TEXTJOIN(", ",TRUE(),IF('Risk Register'!$O$5="1-1",'Risk Register'!$A$5,""),IF('Risk Register'!$O$6="1-1",'Risk Register'!$A$6,""),IF('Risk Register'!$O$7="1-1",'Risk Register'!$A$7,""),IF('Risk Register'!$O$8="1-1",'Risk Register'!$A$8,""),IF('Risk Register'!$O$9="1-1",'Risk Register'!$A$9,""),IF('Risk Register'!$O$10="1-1",'Risk Register'!$A$10,""),IF('Risk Register'!$O$11="1-1",'Risk Register'!$A$11,""),IF('Risk Register'!$O$12="1-1",'Risk Register'!$A$12,""),IF('Risk Register'!$O$13="1-1",'Risk Register'!$A$13,""),IF('Risk Register'!$O$14="1-1",'Risk Register'!$A$14,""),IF('Risk Register'!$O$15="1-1",'Risk Register'!$A$15,""),IF('Risk Register'!$O$16="1-1",'Risk Register'!$A$16,""),IF('Risk Register'!$O$17="1-1",'Risk Register'!$A$17,""),IF('Risk Register'!$O$18="1-1",'Risk Register'!$A$18,""),IF('Risk Register'!$O$19="1-1",'Risk Register'!$A$19,"")) | D9: =TEXTJOIN(", ",TRUE(),IF('Risk Register'!$O$5="1-2",'Risk Register'!$A$5,""),IF('Risk Register'!$O$6="1-2",'Risk Register'!$A$6,""),IF('Risk Register'!$O$7="1-2",'Risk Register'!$A$7,""),IF('Risk Register'!$O$8="1-2",'Risk Register'!$A$8,""),IF('Risk Register'!$O$9="1-2",'Risk Register'!$A$9,""),IF('Risk Register'!$O$10="1-2",'Risk Register'!$A$10,""),IF('Risk Register'!$O$11="1-2",'Risk Register'!$A$11,""),IF('Risk Register'!$O$12="1-2",'Risk Register'!$A$12,""),IF('Risk Register'!$O$13="1-2",'Risk Register'!$A$13,""),IF('Risk Register'!$O$14="1-2",'Risk Register'!$A$14,""),IF('Risk Register'!$O$15="1-2",'Risk Register'!$A$15,""),IF('Risk Register'!$O$16="1-2",'Risk Register'!$A$16,""),IF('Risk Register'!$O$17="1-2",'Risk Register'!$A$17,""),IF('Risk Register'!$O$18="1-2",'Risk Register'!$A$18,""),IF('Risk Register'!$O$19="1-2",'Risk Register'!$A$19,"")) | E9: =TEXTJOIN(", ",TRUE(),IF('Risk Register'!$O$5="1-3",'Risk Register'!$A$5,""),IF('Risk Register'!$O$6="1-3",'Risk Register'!$A$6,""),IF('Risk Register'!$O$7="1-3",'Risk Register'!$A$7,""),IF('Risk Register'!$O$8="1-3",'Risk Register'!$A$8,""),IF('Risk Register'!$O$9="1-3",'Risk Register'!$A$9,""),IF('Risk Register'!$O$10="1-3",'Risk Register'!$A$10,""),IF('Risk Register'!$O$11="1-3",'Risk Register'!$A$11,""),IF('Risk Register'!$O$12="1-3",'Risk Register'!$A$12,""),IF('Risk Register'!$O$13="1-3",'Risk Register'!$A$13,""),IF('Risk Register'!$O$14="1-3",'Risk Register'!$A$14,""),IF('Risk Register'!$O$15="1-3",'Risk Register'!$A$15,""),IF('Risk Register'!$O$16="1-3",'Risk Register'!$A$16,""),IF('Risk Register'!$O$17="1-3",'Risk Register'!$A$17,""),IF('Risk Register'!$O$18="1-3",'Risk Register'!$A$18,""),IF('Risk Register'!$O$19="1-3",'Risk Register'!$A$19,"")) | F9: =TEXTJOIN(", ",TRUE(),IF('Risk Register'!$O$5="1-4",'Risk Register'!$A$5,""),IF('Risk Register'!$O$6="1-4",'Risk Register'!$A$6,""),IF('Risk Register'!$O$7="1-4",'Risk Register'!$A$7,""),IF('Risk Register'!$O$8="1-4",'Risk Register'!$A$8,""),IF('Risk Register'!$O$9="1-4",'Risk Register'!$A$9,""),IF('Risk Register'!$O$10="1-4",'Risk Register'!$A$10,""),IF('Risk Register'!$O$11="1-4",'Risk Register'!$A$11,""),IF('Risk Register'!$O$12="1-4",'Risk Register'!$A$12,""),IF('Risk Register'!$O$13="1-4",'Risk Register'!$A$13,""),IF('Risk Register'!$O$14="1-4",'Risk Register'!$A$14,""),IF('Risk Register'!$O$15="1-4",'Risk Register'!$A$15,""),IF('Risk Register'!$O$16="1-4",'Risk Register'!$A$16,""),IF('Risk Register'!$O$17="1-4",'Risk Register'!$A$17,""),IF('Risk Register'!$O$18="1-4",'Risk Register'!$A$18,""),IF('Risk Register'!$O$19="1-4",'Risk Register'!$A$19,"")) | G9: =TEXTJOIN(", ",TRUE(),IF('Risk Register'!$O$5="1-5",'Risk Register'!$A$5,""),IF('Risk Register'!$O$6="1-5",'Risk Register'!$A$6,""),IF('Risk Register'!$O$7="1-5",'Risk Register'!$A$7,""),IF('Risk Register'!$O$8="1-5",'Risk Register'!$A$8,""),IF('Risk Register'!$O$9="1-5",'Risk Register'!$A$9,""),IF('Risk Register'!$O$10="1-5",'Risk Register'!$A$10,""),IF('Risk Register'!$O$11="1-5",'Risk Register'!$A$11,""),IF('Risk Register'!$O$12="1-5",'Risk Register'!$A$12,""),IF('Risk Register'!$O$13="1-5",'Risk Register'!$A$13,""),IF('Risk Register'!$O$14="1-5",'Risk Register'!$A$14,""),IF('Risk Register'!$O$15="1-5",'Risk Register'!$A$15,""),IF('Risk Register'!$O$16="1-5",'Risk Register'!$A$16,""),IF('Risk Register'!$O$17="1-5",'Risk Register'!$A$17,""),IF('Risk Register'!$O$18="1-5",'Risk Register'!$A$18,""),IF('Risk Register'!$O$19="1-5",'Risk Register'!$A$19,""))
C10: 1 | D10: 2 | E10: 3 | F10: 4 | G10: 5
C11: Impact →
A15: Residual risk (after mitigation)
B16: 5 | C16: =TEXTJOIN(", ",TRUE(),IF('Risk Register'!$P$5="5-1",'Risk Register'!$A$5,""),IF('Risk Register'!$P$6="5-1",'Risk Register'!$A$6,""),IF('Risk Register'!$P$7="5-1",'Risk Register'!$A$7,""),IF('Risk Register'!$P$8="5-1",'Risk Register'!$A$8,""),IF('Risk Register'!$P$9="5-1",'Risk Register'!$A$9,""),IF('Risk Register'!$P$10="5-1",'Risk Register'!$A$10,""),IF('Risk Register'!$P$11="5-1",'Risk Register'!$A$11,""),IF('Risk Register'!$P$12="5-1",'Risk Register'!$A$12,""),IF('Risk Register'!$P$13="5-1",'Risk Register'!$A$13,""),IF('Risk Register'!$P$14="5-1",'Risk Register'!$A$14,""),IF('Risk Register'!$P$15="5-1",'Risk Register'!$A$15,""),IF('Risk Register'!$P$16="5-1",'Risk Register'!$A$16,""),IF('Risk Register'!$P$17="5-1",'Risk Register'!$A$17,""),IF('Risk Register'!$P$18="5-1",'Risk Register'!$A$18,""),IF('Risk Register'!$P$19="5-1",'Risk Register'!$A$19,"")) | D16: =TEXTJOIN(", ",TRUE(),IF('Risk Register'!$P$5="5-2",'Risk Register'!$A$5,""),IF('Risk Register'!$P$6="5-2",'Risk Register'!$A$6,""),IF('Risk Register'!$P$7="5-2",'Risk Register'!$A$7,""),IF('Risk Register'!$P$8="5-2",'Risk Register'!$A$8,""),IF('Risk Register'!$P$9="5-2",'Risk Register'!$A$9,""),IF('Risk Register'!$P$10="5-2",'Risk Register'!$A$10,""),IF('Risk Register'!$P$11="5-2",'Risk Register'!$A$11,""),IF('Risk Register'!$P$12="5-2",'Risk Register'!$A$12,""),IF('Risk Register'!$P$13="5-2",'Risk Register'!$A$13,""),IF('Risk Register'!$P$14="5-2",'Risk Register'!$A$14,""),IF('Risk Register'!$P$15="5-2",'Risk Register'!$A$15,""),IF('Risk Register'!$P$16="5-2",'Risk Register'!$A$16,""),IF('Risk Register'!$P$17="5-2",'Risk Register'!$A$17,""),IF('Risk Register'!$P$18="5-2",'Risk Register'!$A$18,""),IF('Risk Register'!$P$19="5-2",'Risk Register'!$A$19,"")) | E16: =TEXTJOIN(", ",TRUE(),IF('Risk Register'!$P$5="5-3",'Risk Register'!$A$5,""),IF('Risk Register'!$P$6="5-3",'Risk Register'!$A$6,""),IF('Risk Register'!$P$7="5-3",'Risk Register'!$A$7,""),IF('Risk Register'!$P$8="5-3",'Risk Register'!$A$8,""),IF('Risk Register'!$P$9="5-3",'Risk Register'!$A$9,""),IF('Risk Register'!$P$10="5-3",'Risk Register'!$A$10,""),IF('Risk Register'!$P$11="5-3",'Risk Register'!$A$11,""),IF('Risk Register'!$P$12="5-3",'Risk Register'!$A$12,""),IF('Risk Register'!$P$13="5-3",'Risk Register'!$A$13,""),IF('Risk Register'!$P$14="5-3",'Risk Register'!$A$14,""),IF('Risk Register'!$P$15="5-3",'Risk Register'!$A$15,""),IF('Risk Register'!$P$16="5-3",'Risk Register'!$A$16,""),IF('Risk Register'!$P$17="5-3",'Risk Register'!$A$17,""),IF('Risk Register'!$P$18="5-3",'Risk Register'!$A$18,""),IF('Risk Register'!$P$19="5-3",'Risk Register'!$A$19,"")) | F16: =TEXTJOIN(", ",TRUE(),IF('Risk Register'!$P$5="5-4",'Risk Register'!$A$5,""),IF('Risk Register'!$P$6="5-4",'Risk Register'!$A$6,""),IF('Risk Register'!$P$7="5-4",'Risk Register'!$A$7,""),IF('Risk Register'!$P$8="5-4",'Risk Register'!$A$8,""),IF('Risk Register'!$P$9="5-4",'Risk Register'!$A$9,""),IF('Risk Register'!$P$10="5-4",'Risk Register'!$A$10,""),IF('Risk Register'!$P$11="5-4",'Risk Register'!$A$11,""),IF('Risk Register'!$P$12="5-4",'Risk Register'!$A$12,""),IF('Risk Register'!$P$13="5-4",'Risk Register'!$A$13,""),IF('Risk Register'!$P$14="5-4",'Risk Register'!$A$14,""),IF('Risk Register'!$P$15="5-4",'Risk Register'!$A$15,""),IF('Risk Register'!$P$16="5-4",'Risk Register'!$A$16,""),IF('Risk Register'!$P$17="5-4",'Risk Register'!$A$17,""),IF('Risk Register'!$P$18="5-4",'Risk Register'!$A$18,""),IF('Risk Register'!$P$19="5-4",'Risk Register'!$A$19,"")) | G16: =TEXTJOIN(", ",TRUE(),IF('Risk Register'!$P$5="5-5",'Risk Register'!$A$5,""),IF('Risk Register'!$P$6="5-5",'Risk Register'!$A$6,""),IF('Risk Register'!$P$7="5-5",'Risk Register'!$A$7,""),IF('Risk Register'!$P$8="5-5",'Risk Register'!$A$8,""),IF('Risk Register'!$P$9="5-5",'Risk Register'!$A$9,""),IF('Risk Register'!$P$10="5-5",'Risk Register'!$A$10,""),IF('Risk Register'!$P$11="5-5",'Risk Register'!$A$11,""),IF('Risk Register'!$P$12="5-5",'Risk Register'!$A$12,""),IF('Risk Register'!$P$13="5-5",'Risk Register'!$A$13,""),IF('Risk Register'!$P$14="5-5",'Risk Register'!$A$14,""),IF('Risk Register'!$P$15="5-5",'Risk Register'!$A$15,""),IF('Risk Register'!$P$16="5-5",'Risk Register'!$A$16,""),IF('Risk Register'!$P$17="5-5",'Risk Register'!$A$17,""),IF('Risk Register'!$P$18="5-5",'Risk Register'!$A$18,""),IF('Risk Register'!$P$19="5-5",'Risk Register'!$A$19,""))
B17: 4 | C17: =TEXTJOIN(", ",TRUE(),IF('Risk Register'!$P$5="4-1",'Risk Register'!$A$5,""),IF('Risk Register'!$P$6="4-1",'Risk Register'!$A$6,""),IF('Risk Register'!$P$7="4-1",'Risk Register'!$A$7,""),IF('Risk Register'!$P$8="4-1",'Risk Register'!$A$8,""),IF('Risk Register'!$P$9="4-1",'Risk Register'!$A$9,""),IF('Risk Register'!$P$10="4-1",'Risk Register'!$A$10,""),IF('Risk Register'!$P$11="4-1",'Risk Register'!$A$11,""),IF('Risk Register'!$P$12="4-1",'Risk Register'!$A$12,""),IF('Risk Register'!$P$13="4-1",'Risk Register'!$A$13,""),IF('Risk Register'!$P$14="4-1",'Risk Register'!$A$14,""),IF('Risk Register'!$P$15="4-1",'Risk Register'!$A$15,""),IF('Risk Register'!$P$16="4-1",'Risk Register'!$A$16,""),IF('Risk Register'!$P$17="4-1",'Risk Register'!$A$17,""),IF('Risk Register'!$P$18="4-1",'Risk Register'!$A$18,""),IF('Risk Register'!$P$19="4-1",'Risk Register'!$A$19,"")) | D17: =TEXTJOIN(", ",TRUE(),IF('Risk Register'!$P$5="4-2",'Risk Register'!$A$5,""),IF('Risk Register'!$P$6="4-2",'Risk Register'!$A$6,""),IF('Risk Register'!$P$7="4-2",'Risk Register'!$A$7,""),IF('Risk Register'!$P$8="4-2",'Risk Register'!$A$8,""),IF('Risk Register'!$P$9="4-2",'Risk Register'!$A$9,""),IF('Risk Register'!$P$10="4-2",'Risk Register'!$A$10,""),IF('Risk Register'!$P$11="4-2",'Risk Register'!$A$11,""),IF('Risk Register'!$P$12="4-2",'Risk Register'!$A$12,""),IF('Risk Register'!$P$13="4-2",'Risk Register'!$A$13,""),IF('Risk Register'!$P$14="4-2",'Risk Register'!$A$14,""),IF('Risk Register'!$P$15="4-2",'Risk Register'!$A$15,""),IF('Risk Register'!$P$16="4-2",'Risk Register'!$A$16,""),IF('Risk Register'!$P$17="4-2",'Risk Register'!$A$17,""),IF('Risk Register'!$P$18="4-2",'Risk Register'!$A$18,""),IF('Risk Register'!$P$19="4-2",'Risk Register'!$A$19,"")) | E17: =TEXTJOIN(", ",TRUE(),IF('Risk Register'!$P$5="4-3",'Risk Register'!$A$5,""),IF('Risk Register'!$P$6="4-3",'Risk Register'!$A$6,""),IF('Risk Register'!$P$7="4-3",'Risk Register'!$A$7,""),IF('Risk Register'!$P$8="4-3",'Risk Register'!$A$8,""),IF('Risk Register'!$P$9="4-3",'Risk Register'!$A$9,""),IF('Risk Register'!$P$10="4-3",'Risk Register'!$A$10,""),IF('Risk Register'!$P$11="4-3",'Risk Register'!$A$11,""),IF('Risk Register'!$P$12="4-3",'Risk Register'!$A$12,""),IF('Risk Register'!$P$13="4-3",'Risk Register'!$A$13,""),IF('Risk Register'!$P$14="4-3",'Risk Register'!$A$14,""),IF('Risk Register'!$P$15="4-3",'Risk Register'!$A$15,""),IF('Risk Register'!$P$16="4-3",'Risk Register'!$A$16,""),IF('Risk Register'!$P$17="4-3",'Risk Register'!$A$17,""),IF('Risk Register'!$P$18="4-3",'Risk Register'!$A$18,""),IF('Risk Register'!$P$19="4-3",'Risk Register'!$A$19,"")) | F17: =TEXTJOIN(", ",TRUE(),IF('Risk Register'!$P$5="4-4",'Risk Register'!$A$5,""),IF('Risk Register'!$P$6="4-4",'Risk Register'!$A$6,""),IF('Risk Register'!$P$7="4-4",'Risk Register'!$A$7,""),IF('Risk Register'!$P$8="4-4",'Risk Register'!$A$8,""),IF('Risk Register'!$P$9="4-4",'Risk Register'!$A$9,""),IF('Risk Register'!$P$10="4-4",'Risk Register'!$A$10,""),IF('Risk Register'!$P$11="4-4",'Risk Register'!$A$11,""),IF('Risk Register'!$P$12="4-4",'Risk Register'!$A$12,""),IF('Risk Register'!$P$13="4-4",'Risk Register'!$A$13,""),IF('Risk Register'!$P$14="4-4",'Risk Register'!$A$14,""),IF('Risk Register'!$P$15="4-4",'Risk Register'!$A$15,""),IF('Risk Register'!$P$16="4-4",'Risk Register'!$A$16,""),IF('Risk Register'!$P$17="4-4",'Risk Register'!$A$17,""),IF('Risk Register'!$P$18="4-4",'Risk Register'!$A$18,""),IF('Risk Register'!$P$19="4-4",'Risk Register'!$A$19,"")) | G17: =TEXTJOIN(", ",TRUE(),IF('Risk Register'!$P$5="4-5",'Risk Register'!$A$5,""),IF('Risk Register'!$P$6="4-5",'Risk Register'!$A$6,""),IF('Risk Register'!$P$7="4-5",'Risk Register'!$A$7,""),IF('Risk Register'!$P$8="4-5",'Risk Register'!$A$8,""),IF('Risk Register'!$P$9="4-5",'Risk Register'!$A$9,""),IF('Risk Register'!$P$10="4-5",'Risk Register'!$A$10,""),IF('Risk Register'!$P$11="4-5",'Risk Register'!$A$11,""),IF('Risk Register'!$P$12="4-5",'Risk Register'!$A$12,""),IF('Risk Register'!$P$13="4-5",'Risk Register'!$A$13,""),IF('Risk Register'!$P$14="4-5",'Risk Register'!$A$14,""),IF('Risk Register'!$P$15="4-5",'Risk Register'!$A$15,""),IF('Risk Register'!$P$16="4-5",'Risk Register'!$A$16,""),IF('Risk Register'!$P$17="4-5",'Risk Register'!$A$17,""),IF('Risk Register'!$P$18="4-5",'Risk Register'!$A$18,""),IF('Risk Register'!$P$19="4-5",'Risk Register'!$A$19,""))
A18: Likelihood ↑ | B18: 3 | C18: =TEXTJOIN(", ",TRUE(),IF('Risk Register'!$P$5="3-1",'Risk Register'!$A$5,""),IF('Risk Register'!$P$6="3-1",'Risk Register'!$A$6,""),IF('Risk Register'!$P$7="3-1",'Risk Register'!$A$7,""),IF('Risk Register'!$P$8="3-1",'Risk Register'!$A$8,""),IF('Risk Register'!$P$9="3-1",'Risk Register'!$A$9,""),IF('Risk Register'!$P$10="3-1",'Risk Register'!$A$10,""),IF('Risk Register'!$P$11="3-1",'Risk Register'!$A$11,""),IF('Risk Register'!$P$12="3-1",'Risk Register'!$A$12,""),IF('Risk Register'!$P$13="3-1",'Risk Register'!$A$13,""),IF('Risk Register'!$P$14="3-1",'Risk Register'!$A$14,""),IF('Risk Register'!$P$15="3-1",'Risk Register'!$A$15,""),IF('Risk Register'!$P$16="3-1",'Risk Register'!$A$16,""),IF('Risk Register'!$P$17="3-1",'Risk Register'!$A$17,""),IF('Risk Register'!$P$18="3-1",'Risk Register'!$A$18,""),IF('Risk Register'!$P$19="3-1",'Risk Register'!$A$19,"")) | D18: =TEXTJOIN(", ",TRUE(),IF('Risk Register'!$P$5="3-2",'Risk Register'!$A$5,""),IF('Risk Register'!$P$6="3-2",'Risk Register'!$A$6,""),IF('Risk Register'!$P$7="3-2",'Risk Register'!$A$7,""),IF('Risk Register'!$P$8="3-2",'Risk Register'!$A$8,""),IF('Risk Register'!$P$9="3-2",'Risk Register'!$A$9,""),IF('Risk Register'!$P$10="3-2",'Risk Register'!$A$10,""),IF('Risk Register'!$P$11="3-2",'Risk Register'!$A$11,""),IF('Risk Register'!$P$12="3-2",'Risk Register'!$A$12,""),IF('Risk Register'!$P$13="3-2",'Risk Register'!$A$13,""),IF('Risk Register'!$P$14="3-2",'Risk Register'!$A$14,""),IF('Risk Register'!$P$15="3-2",'Risk Register'!$A$15,""),IF('Risk Register'!$P$16="3-2",'Risk Register'!$A$16,""),IF('Risk Register'!$P$17="3-2",'Risk Register'!$A$17,""),IF('Risk Register'!$P$18="3-2",'Risk Register'!$A$18,""),IF('Risk Register'!$P$19="3-2",'Risk Register'!$A$19,"")) | E18: =TEXTJOIN(", ",TRUE(),IF('Risk Register'!$P$5="3-3",'Risk Register'!$A$5,""),IF('Risk Register'!$P$6="3-3",'Risk Register'!$A$6,""),IF('Risk Register'!$P$7="3-3",'Risk Register'!$A$7,""),IF('Risk Register'!$P$8="3-3",'Risk Register'!$A$8,""),IF('Risk Register'!$P$9="3-3",'Risk Register'!$A$9,""),IF('Risk Register'!$P$10="3-3",'Risk Register'!$A$10,""),IF('Risk Register'!$P$11="3-3",'Risk Register'!$A$11,""),IF('Risk Register'!$P$12="3-3",'Risk Register'!$A$12,""),IF('Risk Register'!$P$13="3-3",'Risk Register'!$A$13,""),IF('Risk Register'!$P$14="3-3",'Risk Register'!$A$14,""),IF('Risk Register'!$P$15="3-3",'Risk Register'!$A$15,""),IF('Risk Register'!$P$16="3-3",'Risk Register'!$A$16,""),IF('Risk Register'!$P$17="3-3",'Risk Register'!$A$17,""),IF('Risk Register'!$P$18="3-3",'Risk Register'!$A$18,""),IF('Risk Register'!$P$19="3-3",'Risk Register'!$A$19,"")) | F18: =TEXTJOIN(", ",TRUE(),IF('Risk Register'!$P$5="3-4",'Risk Register'!$A$5,""),IF('Risk Register'!$P$6="3-4",'Risk Register'!$A$6,""),IF('Risk Register'!$P$7="3-4",'Risk Register'!$A$7,""),IF('Risk Register'!$P$8="3-4",'Risk Register'!$A$8,""),IF('Risk Register'!$P$9="3-4",'Risk Register'!$A$9,""),IF('Risk Register'!$P$10="3-4",'Risk Register'!$A$10,""),IF('Risk Register'!$P$11="3-4",'Risk Register'!$A$11,""),IF('Risk Register'!$P$12="3-4",'Risk Register'!$A$12,""),IF('Risk Register'!$P$13="3-4",'Risk Register'!$A$13,""),IF('Risk Register'!$P$14="3-4",'Risk Register'!$A$14,""),IF('Risk Register'!$P$15="3-4",'Risk Register'!$A$15,""),IF('Risk Register'!$P$16="3-4",'Risk Register'!$A$16,""),IF('Risk Register'!$P$17="3-4",'Risk Register'!$A$17,""),IF('Risk Register'!$P$18="3-4",'Risk Register'!$A$18,""),IF('Risk Register'!$P$19="3-4",'Risk Register'!$A$19,"")) | G18: =TEXTJOIN(", ",TRUE(),IF('Risk Register'!$P$5="3-5",'Risk Register'!$A$5,""),IF('Risk Register'!$P$6="3-5",'Risk Register'!$A$6,""),IF('Risk Register'!$P$7="3-5",'Risk Register'!$A$7,""),IF('Risk Register'!$P$8="3-5",'Risk Register'!$A$8,""),IF('Risk Register'!$P$9="3-5",'Risk Register'!$A$9,""),IF('Risk Register'!$P$10="3-5",'Risk Register'!$A$10,""),IF('Risk Register'!$P$11="3-5",'Risk Register'!$A$11,""),IF('Risk Register'!$P$12="3-5",'Risk Register'!$A$12,""),IF('Risk Register'!$P$13="3-5",'Risk Register'!$A$13,""),IF('Risk Register'!$P$14="3-5",'Risk Register'!$A$14,""),IF('Risk Register'!$P$15="3-5",'Risk Register'!$A$15,""),IF('Risk Register'!$P$16="3-5",'Risk Register'!$A$16,""),IF('Risk Register'!$P$17="3-5",'Risk Register'!$A$17,""),IF('Risk Register'!$P$18="3-5",'Risk Register'!$A$18,""),IF('Risk Register'!$P$19="3-5",'Risk Register'!$A$19,""))
B19: 2 | C19: =TEXTJOIN(", ",TRUE(),IF('Risk Register'!$P$5="2-1",'Risk Register'!$A$5,""),IF('Risk Register'!$P$6="2-1",'Risk Register'!$A$6,""),IF('Risk Register'!$P$7="2-1",'Risk Register'!$A$7,""),IF('Risk Register'!$P$8="2-1",'Risk Register'!$A$8,""),IF('Risk Register'!$P$9="2-1",'Risk Register'!$A$9,""),IF('Risk Register'!$P$10="2-1",'Risk Register'!$A$10,""),IF('Risk Register'!$P$11="2-1",'Risk Register'!$A$11,""),IF('Risk Register'!$P$12="2-1",'Risk Register'!$A$12,""),IF('Risk Register'!$P$13="2-1",'Risk Register'!$A$13,""),IF('Risk Register'!$P$14="2-1",'Risk Register'!$A$14,""),IF('Risk Register'!$P$15="2-1",'Risk Register'!$A$15,""),IF('Risk Register'!$P$16="2-1",'Risk Register'!$A$16,""),IF('Risk Register'!$P$17="2-1",'Risk Register'!$A$17,""),IF('Risk Register'!$P$18="2-1",'Risk Register'!$A$18,""),IF('Risk Register'!$P$19="2-1",'Risk Register'!$A$19,"")) -> R-12 | D19: =TEXTJOIN(", ",TRUE(),IF('Risk Register'!$P$5="2-2",'Risk Register'!$A$5,""),IF('Risk Register'!$P$6="2-2",'Risk Register'!$A$6,""),IF('Risk Register'!$P$7="2-2",'Risk Register'!$A$7,""),IF('Risk Register'!$P$8="2-2",'Risk Register'!$A$8,""),IF('Risk Register'!$P$9="2-2",'Risk Register'!$A$9,""),IF('Risk Register'!$P$10="2-2",'Risk Register'!$A$10,""),IF('Risk Register'!$P$11="2-2",'Risk Register'!$A$11,""),IF('Risk Register'!$P$12="2-2",'Risk Register'!$A$12,""),IF('Risk Register'!$P$13="2-2",'Risk Register'!$A$13,""),IF('Risk Register'!$P$14="2-2",'Risk Register'!$A$14,""),IF('Risk Register'!$P$15="2-2",'Risk Register'!$A$15,""),IF('Risk Register'!$P$16="2-2",'Risk Register'!$A$16,""),IF('Risk Register'!$P$17="2-2",'Risk Register'!$A$17,""),IF('Risk Register'!$P$18="2-2",'Risk Register'!$A$18,""),IF('Risk Register'!$P$19="2-2",'Risk Register'!$A$19,"")) -> R-04, R-07 | E19: =TEXTJOIN(", ",TRUE(),IF('Risk Register'!$P$5="2-3",'Risk Register'!$A$5,""),IF('Risk Register'!$P$6="2-3",'Risk Register'!$A$6,""),IF('Risk Register'!$P$7="2-3",'Risk Register'!$A$7,""),IF('Risk Register'!$P$8="2-3",'Risk Register'!$A$8,""),IF('Risk Register'!$P$9="2-3",'Risk Register'!$A$9,""),IF('Risk Register'!$P$10="2-3",'Risk Register'!$A$10,""),IF('Risk Register'!$P$11="2-3",'Risk Register'!$A$11,""),IF('Risk Register'!$P$12="2-3",'Risk Register'!$A$12,""),IF('Risk Register'!$P$13="2-3",'Risk Register'!$A$13,""),IF('Risk Register'!$P$14="2-3",'Risk Register'!$A$14,""),IF('Risk Register'!$P$15="2-3",'Risk Register'!$A$15,""),IF('Risk Register'!$P$16="2-3",'Risk Register'!$A$16,""),IF('Risk Register'!$P$17="2-3",'Risk Register'!$A$17,""),IF('Risk Register'!$P$18="2-3",'Risk Register'!$A$18,""),IF('Risk Register'!$P$19="2-3",'Risk Register'!$A$19,"")) -> R-02, R-05, R-08, R-11 | F19: =TEXTJOIN(", ",TRUE(),IF('Risk Register'!$P$5="2-4",'Risk Register'!$A$5,""),IF('Risk Register'!$P$6="2-4",'Risk Register'!$A$6,""),IF('Risk Register'!$P$7="2-4",'Risk Register'!$A$7,""),IF('Risk Register'!$P$8="2-4",'Risk Register'!$A$8,""),IF('Risk Register'!$P$9="2-4",'Risk Register'!$A$9,""),IF('Risk Register'!$P$10="2-4",'Risk Register'!$A$10,""),IF('Risk Register'!$P$11="2-4",'Risk Register'!$A$11,""),IF('Risk Register'!$P$12="2-4",'Risk Register'!$A$12,""),IF('Risk Register'!$P$13="2-4",'Risk Register'!$A$13,""),IF('Risk Register'!$P$14="2-4",'Risk Register'!$A$14,""),IF('Risk Register'!$P$15="2-4",'Risk Register'!$A$15,""),IF('Risk Register'!$P$16="2-4",'Risk Register'!$A$16,""),IF('Risk Register'!$P$17="2-4",'Risk Register'!$A$17,""),IF('Risk Register'!$P$18="2-4",'Risk Register'!$A$18,""),IF('Risk Register'!$P$19="2-4",'Risk Register'!$A$19,"")) | G19: =TEXTJOIN(", ",TRUE(),IF('Risk Register'!$P$5="2-5",'Risk Register'!$A$5,""),IF('Risk Register'!$P$6="2-5",'Risk Register'!$A$6,""),IF('Risk Register'!$P$7="2-5",'Risk Register'!$A$7,""),IF('Risk Register'!$P$8="2-5",'Risk Register'!$A$8,""),IF('Risk Register'!$P$9="2-5",'Risk Register'!$A$9,""),IF('Risk Register'!$P$10="2-5",'Risk Register'!$A$10,""),IF('Risk Register'!$P$11="2-5",'Risk Register'!$A$11,""),IF('Risk Register'!$P$12="2-5",'Risk Register'!$A$12,""),IF('Risk Register'!$P$13="2-5",'Risk Register'!$A$13,""),IF('Risk Register'!$P$14="2-5",'Risk Register'!$A$14,""),IF('Risk Register'!$P$15="2-5",'Risk Register'!$A$15,""),IF('Risk Register'!$P$16="2-5",'Risk Register'!$A$16,""),IF('Risk Register'!$P$17="2-5",'Risk Register'!$A$17,""),IF('Risk Register'!$P$18="2-5",'Risk Register'!$A$18,""),IF('Risk Register'!$P$19="2-5",'Risk Register'!$A$19,"")) -> R-01
B20: 1 | C20: =TEXTJOIN(", ",TRUE(),IF('Risk Register'!$P$5="1-1",'Risk Register'!$A$5,""),IF('Risk Register'!$P$6="1-1",'Risk Register'!$A$6,""),IF('Risk Register'!$P$7="1-1",'Risk Register'!$A$7,""),IF('Risk Register'!$P$8="1-1",'Risk Register'!$A$8,""),IF('Risk Register'!$P$9="1-1",'Risk Register'!$A$9,""),IF('Risk Register'!$P$10="1-1",'Risk Register'!$A$10,""),IF('Risk Register'!$P$11="1-1",'Risk Register'!$A$11,""),IF('Risk Register'!$P$12="1-1",'Risk Register'!$A$12,""),IF('Risk Register'!$P$13="1-1",'Risk Register'!$A$13,""),IF('Risk Register'!$P$14="1-1",'Risk Register'!$A$14,""),IF('Risk Register'!$P$15="1-1",'Risk Register'!$A$15,""),IF('Risk Register'!$P$16="1-1",'Risk Register'!$A$16,""),IF('Risk Register'!$P$17="1-1",'Risk Register'!$A$17,""),IF('Risk Register'!$P$18="1-1",'Risk Register'!$A$18,""),IF('Risk Register'!$P$19="1-1",'Risk Register'!$A$19,"")) | D20: =TEXTJOIN(", ",TRUE(),IF('Risk Register'!$P$5="1-2",'Risk Register'!$A$5,""),IF('Risk Register'!$P$6="1-2",'Risk Register'!$A$6,""),IF('Risk Register'!$P$7="1-2",'Risk Register'!$A$7,""),IF('Risk Register'!$P$8="1-2",'Risk Register'!$A$8,""),IF('Risk Register'!$P$9="1-2",'Risk Register'!$A$9,""),IF('Risk Register'!$P$10="1-2",'Risk Register'!$A$10,""),IF('Risk Register'!$P$11="1-2",'Risk Register'!$A$11,""),IF('Risk Register'!$P$12="1-2",'Risk Register'!$A$12,""),IF('Risk Register'!$P$13="1-2",'Risk Register'!$A$13,""),IF('Risk Register'!$P$14="1-2",'Risk Register'!$A$14,""),IF('Risk Register'!$P$15="1-2",'Risk Register'!$A$15,""),IF('Risk Register'!$P$16="1-2",'Risk Register'!$A$16,""),IF('Risk Register'!$P$17="1-2",'Risk Register'!$A$17,""),IF('Risk Register'!$P$18="1-2",'Risk Register'!$A$18,""),IF('Risk Register'!$P$19="1-2",'Risk Register'!$A$19,"")) -> R-10 | E20: =TEXTJOIN(", ",TRUE(),IF('Risk Register'!$P$5="1-3",'Risk Register'!$A$5,""),IF('Risk Register'!$P$6="1-3",'Risk Register'!$A$6,""),IF('Risk Register'!$P$7="1-3",'Risk Register'!$A$7,""),IF('Risk Register'!$P$8="1-3",'Risk Register'!$A$8,""),IF('Risk Register'!$P$9="1-3",'Risk Register'!$A$9,""),IF('Risk Register'!$P$10="1-3",'Risk Register'!$A$10,""),IF('Risk Register'!$P$11="1-3",'Risk Register'!$A$11,""),IF('Risk Register'!$P$12="1-3",'Risk Register'!$A$12,""),IF('Risk Register'!$P$13="1-3",'Risk Register'!$A$13,""),IF('Risk Register'!$P$14="1-3",'Risk Register'!$A$14,""),IF('Risk Register'!$P$15="1-3",'Risk Register'!$A$15,""),IF('Risk Register'!$P$16="1-3",'Risk Register'!$A$16,""),IF('Risk Register'!$P$17="1-3",'Risk Register'!$A$17,""),IF('Risk Register'!$P$18="1-3",'Risk Register'!$A$18,""),IF('Risk Register'!$P$19="1-3",'Risk Register'!$A$19,"")) -> R-09 | F20: =TEXTJOIN(", ",TRUE(),IF('Risk Register'!$P$5="1-4",'Risk Register'!$A$5,""),IF('Risk Register'!$P$6="1-4",'Risk Register'!$A$6,""),IF('Risk Register'!$P$7="1-4",'Risk Register'!$A$7,""),IF('Risk Register'!$P$8="1-4",'Risk Register'!$A$8,""),IF('Risk Register'!$P$9="1-4",'Risk Register'!$A$9,""),IF('Risk Register'!$P$10="1-4",'Risk Register'!$A$10,""),IF('Risk Register'!$P$11="1-4",'Risk Register'!$A$11,""),IF('Risk Register'!$P$12="1-4",'Risk Register'!$A$12,""),IF('Risk Register'!$P$13="1-4",'Risk Register'!$A$13,""),IF('Risk Register'!$P$14="1-4",'Risk Register'!$A$14,""),IF('Risk Register'!$P$15="1-4",'Risk Register'!$A$15,""),IF('Risk Register'!$P$16="1-4",'Risk Register'!$A$16,""),IF('Risk Register'!$P$17="1-4",'Risk Register'!$A$17,""),IF('Risk Register'!$P$18="1-4",'Risk Register'!$A$18,""),IF('Risk Register'!$P$19="1-4",'Risk Register'!$A$19,"")) -> R-03, R-06 | G20: =TEXTJOIN(", ",TRUE(),IF('Risk Register'!$P$5="1-5",'Risk Register'!$A$5,""),IF('Risk Register'!$P$6="1-5",'Risk Register'!$A$6,""),IF('Risk Register'!$P$7="1-5",'Risk Register'!$A$7,""),IF('Risk Register'!$P$8="1-5",'Risk Register'!$A$8,""),IF('Risk Register'!$P$9="1-5",'Risk Register'!$A$9,""),IF('Risk Register'!$P$10="1-5",'Risk Register'!$A$10,""),IF('Risk Register'!$P$11="1-5",'Risk Register'!$A$11,""),IF('Risk Register'!$P$12="1-5",'Risk Register'!$A$12,""),IF('Risk Register'!$P$13="1-5",'Risk Register'!$A$13,""),IF('Risk Register'!$P$14="1-5",'Risk Register'!$A$14,""),IF('Risk Register'!$P$15="1-5",'Risk Register'!$A$15,""),IF('Risk Register'!$P$16="1-5",'Risk Register'!$A$16,""),IF('Risk Register'!$P$17="1-5",'Risk Register'!$A$17,""),IF('Risk Register'!$P$18="1-5",'Risk Register'!$A$18,""),IF('Risk Register'!$P$19="1-5",'Risk Register'!$A$19,""))
C21: 1 | D21: 2 | E21: 3 | F21: 4 | G21: 5
C22: Impact →

Sheet Risk Register
A1: 340 Collective Risk Register
A2: Yellow = your input. White = automatic. Scores: Likelihood x Impact (1 to 25).
O3: Helper columns (don't edit)
A4: Risk ID | B4: Category | C4: Description | D4: Likelihood (1-5) | E4: Impact (1-5) | F4: Risk Score | G4: Rating | H4: Mitigation | I4: Owner | J4: Residual Likelihood (1-5) | K4: Residual Impact (1-5) | L4: Residual Risk | M4: Residual Rating | N4: Review Date | O4: Heat key | P4: Residual heat key | Q4: Rank helper
A5: R-01 | B5: Security | C5: AWS root or admin credentials compromised (no MFA, leaked access keys), giving an attacker full control of the account. | D5: 4 | E5: 5 | F5: =IF(AND(D5<>"",E5<>""),D5*E5,"") -> 20 | G5: =IF(F5="","",IF(F5>=15,"High",IF(F5>=8,"Medium","Low"))) -> High | H5: Enforce MFA on root and all IAM users; delete root access keys; use least-privilege IAM roles; alert on root sign-in. | I5: Account Admin (ISSM) | J5: 2 | K5: 5 | L5: =IF(AND(J5<>"",K5<>""),J5*K5,"") -> 10 | M5: =IF(L5="","",IF(L5>=15,"High",IF(L5>=8,"Medium","Low"))) -> Medium | N5: 46341 | O5: =IF(F5="","",D5&"-"&E5) -> 4-5 | P5: =IF(L5="","",J5&"-"&K5) -> 2-5 | Q5: =IF(F5="","",F5+(1000-ROW())/10000) -> 20.0995
A6: R-02 | B6: Vendor | C6: Stripe payment links are leaked or misused (card testing, fake links sent to clients), causing chargebacks, fees, and possible Stripe account suspension. | D6: 4 | E6: 4 | F6: =IF(AND(D6<>"",E6<>""),D6*E6,"") -> 16 | G6: =IF(F6="","",IF(F6>=15,"High",IF(F6>=8,"Medium","Low"))) -> High | H6: Keep Stripe Radar fraud screening on; enforce MFA on the Stripe dashboard; validate webhook signatures and charged amounts against the catalog; store the Stripe secret key in AWS SSM Parameter Store (not in code); deactivate only genuinely one-off links after use; tell clients how legitimate payment links are shared. | I6: Business Owner | J6: 2 | K6: 3 | L6: =IF(AND(J6<>"",K6<>""),J6*K6,"") -> 6 | M6: =IF(L6="","",IF(L6>=15,"High",IF(L6>=8,"Medium","Low"))) -> Low | N6: 46338 | O6: =IF(F6="","",D6&"-"&E6) -> 4-4 | P6: =IF(L6="","",J6&"-"&K6) -> 2-3 | Q6: =IF(F6="","",F6+(1000-ROW())/10000) -> 16.0994
A7: R-03 | B7: Vendor | C7: The 340collective.com domain expires because a renewal is missed (auto-renew off or an expired card), taking the website and email offline; someone else could buy the domain. | D7: 2 | E7: 4 | F7: =IF(AND(D7<>"",E7<>""),D7*E7,"") -> 8 | G7: =IF(F7="","",IF(F7>=15,"High",IF(F7>=8,"Medium","Low"))) -> Medium | H7: Turn on auto-renew; renew for several years; keep a backup payment card; enable registrar lock and MFA on the registrar account; set a calendar reminder 60 days before expiry. | I7: Business Owner | J7: 1 | K7: 4 | L7: =IF(AND(J7<>"",K7<>""),J7*K7,"") -> 4 | M7: =IF(L7="","",IF(L7>=15,"High",IF(L7>=8,"Medium","Low"))) -> Low | N7: 46368 | O7: =IF(F7="","",D7&"-"&E7) -> 2-4 | P7: =IF(L7="","",J7&"-"&K7) -> 1-4 | Q7: =IF(F7="","",F7+(1000-ROW())/10000) -> 8.0993
A8: R-04 | B8: Business | C8: Client photos and videos are lost (accidental deletion, ransomware, drive or account failure) with no working backup, so finished or in-progress client work can't be recovered. | D8: 3 | E8: 4 | F8: =IF(AND(D8<>"",E8<>""),D8*E8,"") -> 12 | G8: =IF(F8="","",IF(F8>=15,"High",IF(F8>=8,"Medium","Low"))) -> Medium | H8: Keep automatic backups with versioning; store a second copy offsite (3-2-1 rule); limit who can delete files; test restoring a file every quarter. | I8: Business Owner | J8: 2 | K8: 2 | L8: =IF(AND(J8<>"",K8<>""),J8*K8,"") -> 4 | M8: =IF(L8="","",IF(L8>=15,"High",IF(L8>=8,"Medium","Low"))) -> Low | N8: 46368 | O8: =IF(F8="","",D8&"-"&E8) -> 3-4 | P8: =IF(L8="","",J8&"-"&K8) -> 2-2 | Q8: =IF(F8="","",F8+(1000-ROW())/10000) -> 12.0992
A9: R-05 | B9: Security | C9: A phishing email tricks a team member into giving up their email or AWS login | D9: 4 | E9: 4 | F9: =IF(AND(D9<>"",E9<>""),D9*E9,"") -> 16 | G9: =IF(F9="","",IF(F9>=15,"High",IF(F9>=8,"Medium","Low"))) -> High | H9: MFA on every account; password manager; short phishing training; report-suspicious-email process. | I9: Business Owner | J9: 2 | K9: 3 | L9: =IF(AND(J9<>"",K9<>""),J9*K9,"") -> 6 | M9: =IF(L9="","",IF(L9>=15,"High",IF(L9>=8,"Medium","Low"))) -> Low | N9: 46368 | O9: =IF(F9="","",D9&"-"&E9) -> 4-4 | P9: =IF(L9="","",J9&"-"&K9) -> 2-3 | Q9: =IF(F9="","",F9+(1000-ROW())/10000) -> 16.0991
A10: R-06 | B10: Security | C10: The GitHub account is compromised and an attacker changes the website or infrastructure code. | D10: 2 | E10: 5 | F10: 10 | G10: =IF(F10="","",IF(F10>=15,"High",IF(F10>=8,"Medium","Low"))) -> Medium | H10: MFA on GitHub; branch protection with required PR approval; few admins; remove unused connected apps. | I10: ISSM | J10: 1 | K10: 4 | L10: =IF(AND(J10<>"",K10<>""),J10*K10,"") -> 4 | M10: =IF(L10="","",IF(L10>=15,"High",IF(L10>=8,"Medium","Low"))) -> Low | N10: 46368 | O10: =IF(F10="","",D10&"-"&E10) -> 2-5 | P10: =IF(L10="","",J10&"-"&K10) -> 1-4 | Q10: =IF(F10="","",F10+(1000-ROW())/10000) -> 10.099
A11: R-07 | B11: Vendor | C11: An AWS outage takes the website, lead forms, or payments offline. | D11: 2 | E11: 3 | F11: =IF(AND(D11<>"",E11<>""),D11*E11,"") -> 6 | G11: Medium | H11: CloudFront caching; infrastructure in CloudFormation so it can be redeployed; documented recovery steps. | I11: ISSE | J11: 2 | K11: 2 | L11: =IF(AND(J11<>"",K11<>""),J11*K11,"") -> 4 | M11: =IF(L11="","",IF(L11>=15,"High",IF(L11>=8,"Medium","Low"))) -> Low | N11: 46368 | O11: =IF(F11="","",D11&"-"&E11) -> 2-3 | P11: =IF(L11="","",J11&"-"&K11) -> 2-2 | Q11: =IF(F11="","",F11+(1000-ROW())/10000) -> 6.0989
A12: R-08 | B12: Business | C12: Only one person knows how the platform works or holds admin access. | D12: 4 | E12: 4 | F12: =IF(AND(D12<>"",E12<>""),D12*E12,"") -> 16 | G12: =IF(F12="","",IF(F12>=15,"High",IF(F12>=8,"Medium","Low"))) -> High | H12: Written runbooks; a second trusted admin with emergency access; shared password vault; cross-training. | I12: Business Owner | J12: 2 | K12: 3 | L12: =IF(AND(J12<>"",K12<>""),J12*K12,"") -> 6 | M12: =IF(L12="","",IF(L12>=15,"High",IF(L12>=8,"Medium","Low"))) -> Low | N12: 46368 | O12: =IF(F12="","",D12&"-"&E12) -> 4-4 | P12: =IF(L12="","",J12&"-"&K12) -> 2-3 | Q12: =IF(F12="","",F12+(1000-ROW())/10000) -> 16.0988
A13: R-09 | B13: Business | C13: The AI blog publishes wrong, harmful, or copied content, damaging reputation. | D13: 3 | E13: 3 | F13: =IF(AND(D13<>"",E13<>""),D13*E13,"") -> 9 | G13: =IF(F13="","",IF(F13>=15,"High",IF(F13>=8,"Medium","Low"))) -> Medium | H13: Human review before publishing; content guidelines; fact-checking; disclose AI use. | I13: Business Owner | J13: 1 | K13: 3 | L13: =IF(AND(J13<>"",K13<>""),J13*K13,"") -> 3 | M13: =IF(L13="","",IF(L13>=15,"High",IF(L13>=8,"Medium","Low"))) -> Low | N13: 46368 | O13: =IF(F13="","",D13&"-"&E13) -> 3-3 | P13: =IF(L13="","",J13&"-"&K13) -> 1-3 | Q13: =IF(F13="","",F13+(1000-ROW())/10000) -> 9.0987
A14: R-10 | B14: Business | C14: AWS costs exceed budget (a forgotten service, abuse, or free tier expiring). | D14: 3 | E14: 3 | F14: =IF(AND(D14<>"",E14<>""),D14*E14,"") -> 9 | G14: =IF(F14="","",IF(F14>=15,"High",IF(F14>=8,"Medium","Low"))) -> Medium | H14: AWS Budgets alerts at $1, $5, $10; tear down after evidence; check quotas first. | I14: ISSM | J14: 1 | K14: 2 | L14: =IF(AND(J14<>"",K14<>""),J14*K14,"") -> 2 | M14: =IF(L14="","",IF(L14>=15,"High",IF(L14>=8,"Medium","Low"))) -> Low | N14: 46368 | O14: =IF(F14="","",D14&"-"&E14) -> 3-3 | P14: =IF(L14="","",J14&"-"&K14) -> 1-2 | Q14: =IF(F14="","",F14+(1000-ROW())/10000) -> 9.0986
A15: R-11 | B15: Vendor | C15: A third-party tool (Jira, newsletter, Stripe) is breached and exposes client data. | D15: 2 | E15: 4 | F15: =IF(AND(D15<>"",E15<>""),D15*E15,"") -> 8 | G15: =IF(F15="","",IF(F15>=15,"High",IF(F15>=8,"Medium","Low"))) -> Medium | H15: Collect minimum client data; MFA on vendor accounts; check vendor security reports; remove unused tools. | I15: Business Owner | J15: 2 | K15: 3 | L15: =IF(AND(J15<>"",K15<>""),J15*K15,"") -> 6 | M15: =IF(L15="","",IF(L15>=15,"High",IF(L15>=8,"Medium","Low"))) -> Low | N15: 46368 | O15: =IF(F15="","",D15&"-"&E15) -> 2-4 | P15: =IF(L15="","",J15&"-"&K15) -> 2-3 | Q15: =IF(F15="","",F15+(1000-ROW())/10000) -> 8.0985
A16: R-12 | B16: Security | C16: Bots abuse the website lead form with spam or malicious input. | D16: 3 | E16: 2 | F16: =IF(AND(D16<>"",E16<>""),D16*E16,"") -> 6 | G16: =IF(F16="","",IF(F16>=15,"High",IF(F16>=8,"Medium","Low"))) -> Low | H16: API Gateway throttling (free); input validation; alert on unusual volume. | I16: ISSE | J16: 2 | K16: 1 | L16: =IF(AND(J16<>"",K16<>""),J16*K16,"") -> 2 | M16: =IF(L16="","",IF(L16>=15,"High",IF(L16>=8,"Medium","Low"))) -> Low | N16: 46368 | O16: =IF(F16="","",D16&"-"&E16) -> 3-2 | P16: =IF(L16="","",J16&"-"&K16) -> 2-1 | Q16: =IF(F16="","",F16+(1000-ROW())/10000) -> 6.0984
A17: R-13 | F17: =IF(AND(D17<>"",E17<>""),D17*E17,"") | G17: =IF(F17="","",IF(F17>=15,"High",IF(F17>=8,"Medium","Low"))) | L17: =IF(AND(J17<>"",K17<>""),J17*K17,"") | M17: =IF(L17="","",IF(L17>=15,"High",IF(L17>=8,"Medium","Low"))) | O17: =IF(F17="","",D17&"-"&E17) | P17: =IF(L17="","",J17&"-"&K17) | Q17: =IF(F17="","",F17+(1000-ROW())/10000)
A18: R-14 | F18: =IF(AND(D18<>"",E18<>""),D18*E18,"") | G18: =IF(F18="","",IF(F18>=15,"High",IF(F18>=8,"Medium","Low"))) | L18: =IF(AND(J18<>"",K18<>""),J18*K18,"") | M18: =IF(L18="","",IF(L18>=15,"High",IF(L18>=8,"Medium","Low"))) | O18: =IF(F18="","",D18&"-"&E18) | P18: =IF(L18="","",J18&"-"&K18) | Q18: =IF(F18="","",F18+(1000-ROW())/10000)
A19: R-15 | F19: =IF(AND(D19<>"",E19<>""),D19*E19,"") | G19: =IF(F19="","",IF(F19>=15,"High",IF(F19>=8,"Medium","Low"))) | L19: =IF(AND(J19<>"",K19<>""),J19*K19,"") | M19: =IF(L19="","",IF(L19>=15,"High",IF(L19>=8,"Medium","Low"))) | O19: =IF(F19="","",D19&"-"&E19) | P19: =IF(L19="","",J19&"-"&K19) | Q19: =IF(F19="","",F19+(1000-ROW())/10000)

Sheet Summary
A1: Risk Summary: Top 5 Risks
A2: The table fills in automatically (highest inherent score first). Write your half-page summary in the yellow box.
A4: Rank | B4: Risk ID | C4: Description | D4: Score | E4: Rating | F4: Owner | G4: Residual | H4: Review Date
A5: 1 | B5: {=IFERROR(INDEX('Risk Register'!$A$5:$A$19,MATCH(LARGE('Risk Register'!$Q$5:$Q$19,1),'Risk Register'!$Q$5:$Q$19,0)),"")} -> R-01 | C5: {=IFERROR(INDEX('Risk Register'!$C$5:$C$19,MATCH(LARGE('Risk Register'!$Q$5:$Q$19,1),'Risk Register'!$Q$5:$Q$19,0))&"","")} -> AWS root or admin credentials compromised (no MFA, leaked access keys), giving an attacker full control of the account. | D5: {=IFERROR(INDEX('Risk Register'!$F$5:$F$19,MATCH(LARGE('Risk Register'!$Q$5:$Q$19,1),'Risk Register'!$Q$5:$Q$19,0)),"")} -> 20 | E5: {=IFERROR(INDEX('Risk Register'!$G$5:$G$19,MATCH(LARGE('Risk Register'!$Q$5:$Q$19,1),'Risk Register'!$Q$5:$Q$19,0)),"")} -> High | F5: {=IFERROR(INDEX('Risk Register'!$I$5:$I$19,MATCH(LARGE('Risk Register'!$Q$5:$Q$19,1),'Risk Register'!$Q$5:$Q$19,0))&"","")} -> Account Admin (ISSM) | G5: {=IFERROR(INDEX('Risk Register'!$L$5:$L$19,MATCH(LARGE('Risk Register'!$Q$5:$Q$19,1),'Risk Register'!$Q$5:$Q$19,0)),"")} -> 10 | H5: {=IFERROR(INDEX('Risk Register'!$N$5:$N$19,MATCH(LARGE('Risk Register'!$Q$5:$Q$19,1),'Risk Register'!$Q$5:$Q$19,0)),"")} -> 46341
A6: 2 | B6: {=IFERROR(INDEX('Risk Register'!$A$5:$A$19,MATCH(LARGE('Risk Register'!$Q$5:$Q$19,2),'Risk Register'!$Q$5:$Q$19,0)),"")} -> R-02 | C6: {=IFERROR(INDEX('Risk Register'!$C$5:$C$19,MATCH(LARGE('Risk Register'!$Q$5:$Q$19,2),'Risk Register'!$Q$5:$Q$19,0))&"","")} -> Stripe payment links are leaked or misused (card testing, fake links sent to clients), causing chargebacks, fees, and possible Stripe account suspension. | D6: {=IFERROR(INDEX('Risk Register'!$F$5:$F$19,MATCH(LARGE('Risk Register'!$Q$5:$Q$19,2),'Risk Register'!$Q$5:$Q$19,0)),"")} -> 16 | E6: {=IFERROR(INDEX('Risk Register'!$G$5:$G$19,MATCH(LARGE('Risk Register'!$Q$5:$Q$19,2),'Risk Register'!$Q$5:$Q$19,0)),"")} -> High | F6: {=IFERROR(INDEX('Risk Register'!$I$5:$I$19,MATCH(LARGE('Risk Register'!$Q$5:$Q$19,2),'Risk Register'!$Q$5:$Q$19,0))&"","")} -> Business Owner | G6: {=IFERROR(INDEX('Risk Register'!$L$5:$L$19,MATCH(LARGE('Risk Register'!$Q$5:$Q$19,2),'Risk Register'!$Q$5:$Q$19,0)),"")} -> 6 | H6: {=IFERROR(INDEX('Risk Register'!$N$5:$N$19,MATCH(LARGE('Risk Register'!$Q$5:$Q$19,2),'Risk Register'!$Q$5:$Q$19,0)),"")} -> 46338
